<?xml version="1.0" ?>
<!-- =================================================================================== -->
<!-- |    This document was autogenerated by xacro from /home/leus/ros/hydro/src/rtm-ros-robotics/rtmros_gazebo/hrpsys_gazebo_tutorials/environment_models/large_box/model6.urdf.xacro | -->
<!-- |    EDITING THIS FILE BY HAND IS NOT RECOMMENDED                                 | -->
<!-- =================================================================================== -->
<robot name="large_box" xmlns:body="http://playerstage.sourceforge.net/gazebo/xmlschema/#body" xmlns:controller="http://playerstage.sourceforge.net/gazebo/xmlschema/#controller" xmlns:gazebo="http://playerstage.sourceforge.net/gazebo/xmlschema/#gz" xmlns:geom="http://playerstage.sourceforge.net/gazebo/xmlschema/#geom" xmlns:interface="http://playerstage.sourceforge.net/gazebo/xmlschema/#interface" xmlns:joint="http://playerstage.sourceforge.net/gazebo/xmlschema/#joint" xmlns:model="http://playerstage.sourceforge.net/gazebo/xmlschema/#model" xmlns:physics="http://playerstage.sourceforge.net/gazebo/xmlschema/#physics" xmlns:renderable="http://playerstage.sourceforge.net/gazebo/xmlschema/#renderable" xmlns:rendering="http://playerstage.sourceforge.net/gazebo/xmlschema/#rendering" xmlns:sensor="http://playerstage.sourceforge.net/gazebo/xmlschema/#sensor" xmlns:xacro="http://www.ros.org/wiki/xacro" xmlns:xi="http://www.w3.org/2001/XInclude">
  <gazebo>
    <static>false</static>
  </gazebo>
  <link name="nil_link6">
    <visual>
      <origin xyz="0 0 0"/>
      <geometry>
        <box size="0.80 0.44 0.85"/>
      </geometry>
    </visual>
    <collision>
      <origin xyz="0 0 0"/>
      <geometry>
        <box size="0.80 0.44 0.85"/>
      </geometry>
    </collision>
    <inertial>
      <mass value="10"/>
      <origin rpy="0 0 0" xyz="0.0 0.0 0.5"/>
      <inertia ixx="10.0" ixy="0" ixz="0" iyy="5.7411" iyz="0" izz="0.788"/>
    </inertial>
  </link>
  <gazebo reference="nil_link6">
    <kp>1.000000e+06</kp>
    <kd>100.0</kd>
    <mu1>0.1</mu1>
    <mu2>0.1</mu2>
    <fdir1>1.0 0.0 0.0</fdir1>
  </gazebo>
  <gazebo reference="nil_link6">
    <material>Gazebo/Blue</material>
  </gazebo>
  <gazebo>
    <plugin filename="libAddForcePlugin2.so" name="simple_box_add_force_plugin2">
      <objname>obj6</objname>
      <linkname1>LARM_LINK6</linkname1>
      <linkname2>RARM_LINK6</linkname2>
    </plugin>
    <plugin filename="libGetVelPlugin.so" name="simple_box_get_vel_plugin">
      <objname>obj6</objname>
      <linkname>nil_link6</linkname>
    </plugin>
    <plugin filename="libSetVelPlugin.so" name="simple_box_set_vel_plugin">
      <objname>obj6</objname>
      <linkname>nil_link6</linkname>
    </plugin>
  </gazebo>
  <link name="LARM_LINK6">
    <visual>
      <origin rpy="0 -0 0" xyz="0 0 0"/>
      <geometry>
        <mesh filename="package://hrpsys_gazebo_tutorials/robot_models/HRP3HAND_L/meshes/LARM_LINK6_mesh.dae" scale="1 1 1"/>
      </geometry>
    </visual>
    <collision>
      <origin rpy="0 -0 0" xyz="0 0 0"/>
      <geometry>
        <mesh filename="package://hrpsys_gazebo_tutorials/robot_models/HRP3HAND_L/meshes/LARM_LINK6_mesh.dae" scale="1 1 1"/>
      </geometry>
    </collision>
    <inertial>
      <mass value="0.001"/>
      <origin rpy="0 -0 0" xyz="0.00067085 0.00738842 -0.085722"/>
      <inertia ixx="1e-02" ixy="0" ixz="0" iyy="1e-02" iyz="0" izz="1e-02"/>
    </inertial>
  </link>
  <gazebo reference="LARM_LINK6">
    <mu1>0.9</mu1>
    <mu2>0.9</mu2>
  </gazebo>
  <link name="L_INDEXMP_R_LINK">
    <visual>
      <origin rpy="0 -0 0" xyz="0 -0.0102 -0.1547"/>
      <geometry>
        <mesh filename="package://hrpsys_gazebo_tutorials/robot_models/HRP3HAND_L/meshes/L_INDEXMP_R_LINK_mesh.dae" scale="1 1 1"/>
      </geometry>
    </visual>
    <collision>
      <origin rpy="0 -0 0" xyz="0 -0.0102 -0.1547"/>
      <geometry>
        <mesh filename="package://hrpsys_gazebo_tutorials/robot_models/HRP3HAND_L/meshes/L_INDEXMP_R_LINK_mesh.dae" scale="1 1 1"/>
      </geometry>
    </collision>
    <inertial>
      <mass value="0.001"/>
      <origin rpy="0 -0 0" xyz="0.00509194 0.00581104 6.273e-05"/>
      <inertia ixx="1e-02" ixy="0" ixz="0" iyy="1e-02" iyz="0" izz="1e-02"/>
    </inertial>
  </link>
  <gazebo reference="L_INDEXMP_R_LINK">
    <mu1>0.9</mu1>
    <mu2>0.9</mu2>
  </gazebo>
  <link name="L_INDEXMP_P_LINK">
    <visual>
      <origin rpy="0 -0 0" xyz="0.02 0 0"/>
      <geometry>
        <mesh filename="package://hrpsys_gazebo_tutorials/robot_models/HRP3HAND_L/meshes/L_INDEXMP_P_LINK_mesh.dae" scale="1 1 1"/>
      </geometry>
    </visual>
    <collision>
      <origin rpy="0 -0 0" xyz="0.02 0 0"/>
      <geometry>
        <mesh filename="package://hrpsys_gazebo_tutorials/robot_models/HRP3HAND_L/meshes/L_INDEXMP_P_LINK_mesh.dae" scale="1 1 1"/>
      </geometry>
    </collision>
    <inertial>
      <mass value="0.001"/>
      <origin rpy="0 -0 0" xyz="-0.00078463 -0.00129762 -0.0281757"/>
      <inertia ixx="1e-02" ixy="0" ixz="0" iyy="1e-02" iyz="0" izz="1e-02"/>
    </inertial>
  </link>
  <gazebo reference="L_INDEXMP_P_LINK">
    <mu1>0.9</mu1>
    <mu2>0.9</mu2>
  </gazebo>
  <link name="L_INDEXPIP_R_LINK">
    <visual>
      <origin rpy="0 -0 0" xyz="0 -0.01125 -0.055"/>
      <geometry>
        <mesh filename="package://hrpsys_gazebo_tutorials/robot_models/HRP3HAND_L/meshes/L_INDEXPIP_R_LINK_mesh.dae" scale="1 1 1"/>
      </geometry>
    </visual>
    <collision>
      <origin rpy="0 -0 0" xyz="0 -0.01125 -0.055"/>
      <geometry>
        <mesh filename="package://hrpsys_gazebo_tutorials/robot_models/HRP3HAND_L/meshes/L_INDEXPIP_R_LINK_mesh.dae" scale="1 1 1"/>
      </geometry>
    </collision>
    <inertial>
      <mass value="0.001"/>
      <origin rpy="0 -0 0" xyz="0.0210676 -0.0134797 -0.0204042"/>
      <inertia ixx="1e-02" ixy="0" ixz="0" iyy="1e-02" iyz="0" izz="1e-02"/>
    </inertial>
  </link>
  <gazebo reference="L_INDEXPIP_R_LINK">
    <mu1>0.9</mu1>
    <mu2>0.9</mu2>
  </gazebo>
  <link name="L_MIDDLEPIP_R_LINK">
    <visual>
      <origin rpy="0 -0 0" xyz="0 -0.02145 -0.2097"/>
      <geometry>
        <mesh filename="package://hrpsys_gazebo_tutorials/robot_models/HRP3HAND_L/meshes/L_MIDDLEPIP_R_LINK_mesh.dae" scale="1 1 1"/>
      </geometry>
    </visual>
    <collision>
      <origin rpy="0 -0 0" xyz="0 -0.02145 -0.2097"/>
      <geometry>
        <mesh filename="package://hrpsys_gazebo_tutorials/robot_models/HRP3HAND_L/meshes/L_MIDDLEPIP_R_LINK_mesh.dae" scale="1 1 1"/>
      </geometry>
    </collision>
    <inertial>
      <mass value="0.001"/>
      <origin rpy="0 -0 0" xyz="-0.0171953 -0.0140037 -0.0195553"/>
      <inertia ixx="1e-02" ixy="0" ixz="0" iyy="1e-02" iyz="0" izz="1e-02"/>
    </inertial>
  </link>
  <gazebo reference="L_MIDDLEPIP_R_LINK">
    <mu1>0.9</mu1>
    <mu2>0.9</mu2>
  </gazebo>
  <link name="L_THUMBCM_Y_LINK">
    <visual>
      <origin rpy="0 -0 0" xyz="0 -0.0102 -0.1292"/>
      <geometry>
        <mesh filename="package://hrpsys_gazebo_tutorials/robot_models/HRP3HAND_L/meshes/L_THUMBCM_Y_LINK_mesh.dae" scale="1 1 1"/>
      </geometry>
    </visual>
    <collision>
      <origin rpy="0 -0 0" xyz="0 -0.0102 -0.1292"/>
      <geometry>
        <mesh filename="package://hrpsys_gazebo_tutorials/robot_models/HRP3HAND_L/meshes/L_THUMBCM_Y_LINK_mesh.dae" scale="1 1 1"/>
      </geometry>
    </collision>
    <inertial>
      <mass value="0.001"/>
      <origin rpy="0 -0 0" xyz="0.0314882 -0.00644999 0.00140644"/>
      <inertia ixx="1e-02" ixy="0" ixz="0" iyy="1e-02" iyz="0" izz="1e-02"/>
    </inertial>
  </link>
  <gazebo reference="L_THUMBCM_Y_LINK">
    <mu1>0.9</mu1>
    <mu2>0.9</mu2>
  </gazebo>
  <link name="L_THUMBCM_P_LINK">
    <visual>
      <origin rpy="0 -0 0" xyz="0.045 0 0"/>
      <geometry>
        <mesh filename="package://hrpsys_gazebo_tutorials/robot_models/HRP3HAND_L/meshes/L_THUMBCM_P_LINK_mesh.dae" scale="1 1 1"/>
      </geometry>
    </visual>
    <collision>
      <origin rpy="0 -0 0" xyz="0.045 0 0"/>
      <geometry>
        <mesh filename="package://hrpsys_gazebo_tutorials/robot_models/HRP3HAND_L/meshes/L_THUMBCM_P_LINK_mesh.dae" scale="1 1 1"/>
      </geometry>
    </collision>
    <inertial>
      <mass value="0.001"/>
      <origin rpy="0 -0 0" xyz="0.00682086 -0.013234 -0.0305205"/>
      <inertia ixx="1e-02" ixy="0" ixz="0" iyy="1e-02" iyz="0" izz="1e-02"/>
    </inertial>
  </link>
  <gazebo reference="L_THUMBCM_P_LINK">
    <mu1>0.9</mu1>
    <mu2>0.9</mu2>
  </gazebo>
  <joint name="L_INDEXMP_R" type="revolute">
    <parent link="LARM_LINK6"/>
    <child link="L_INDEXMP_R_LINK"/>
    <origin rpy="0 -0 0 " xyz="0 -0.0102 -0.1547"/>
    <axis xyz="-1 0 0"/>
    <limit effort="100" lower="-0.261799" upper="1.6057" velocity="0.5"/>
    <dynamics damping="0.2" friction="0"/>
  </joint>
  <transmission name="L_INDEXMP_R_trans" type="pr2_mechanism_model/SimpleTransmission">
    <actuator name="L_INDEXMP_R_motor"/>
    <joint name="L_INDEXMP_R"/>
    <mechanicalReduction>1</mechanicalReduction>
  </transmission>
  <gazebo reference="L_INDEXMP_R">
    <cfmDamping>0.4</cfmDamping>
  </gazebo>
  <joint name="L_INDEXMP_P" type="revolute">
    <parent link="L_INDEXMP_R_LINK"/>
    <child link="L_INDEXMP_P_LINK"/>
    <origin rpy="0 -0 0 " xyz="0.02 0 0"/>
    <axis xyz="0 -1 0"/>
    <limit effort="100" lower="-0" upper="1.5708" velocity="0.5"/>
    <dynamics damping="0.2" friction="0"/>
  </joint>
  <transmission name="L_INDEXMP_P_trans" type="pr2_mechanism_model/SimpleTransmission">
    <actuator name="L_INDEXMP_P_motor"/>
    <joint name="L_INDEXMP_P"/>
    <mechanicalReduction>1</mechanicalReduction>
  </transmission>
  <gazebo reference="L_INDEXMP_P">
    <cfmDamping>0.4</cfmDamping>
  </gazebo>
  <joint name="L_INDEXPIP_R" type="revolute">
    <parent link="L_INDEXMP_P_LINK"/>
    <child link="L_INDEXPIP_R_LINK"/>
    <origin rpy="0 -0 0 " xyz="0 -0.01125 -0.055"/>
    <axis xyz="-1 0 0"/>
    <limit effort="100" lower="-0.698132" upper="2.00713" velocity="0.5"/>
    <dynamics damping="0.2" friction="0"/>
  </joint>
  <transmission name="L_INDEXPIP_R_trans" type="pr2_mechanism_model/SimpleTransmission">
    <actuator name="L_INDEXPIP_R_motor"/>
    <joint name="L_INDEXPIP_R"/>
    <mechanicalReduction>1</mechanicalReduction>
  </transmission>
  <gazebo reference="L_INDEXPIP_R">
    <cfmDamping>0.4</cfmDamping>
  </gazebo>
  <joint name="L_MIDDLEPIP_R" type="revolute">
    <parent link="LARM_LINK6"/>
    <child link="L_MIDDLEPIP_R_LINK"/>
    <origin rpy="0 -0 0 " xyz="0 -0.02145 -0.2097"/>
    <axis xyz="-1 0 0"/>
    <limit effort="100" lower="-0.698132" upper="2.00713" velocity="0.5"/>
    <dynamics damping="0.2" friction="0"/>
  </joint>
  <transmission name="L_MIDDLEPIP_R_trans" type="pr2_mechanism_model/SimpleTransmission">
    <actuator name="L_MIDDLEPIP_R_motor"/>
    <joint name="L_MIDDLEPIP_R"/>
    <mechanicalReduction>1</mechanicalReduction>
  </transmission>
  <gazebo reference="L_MIDDLEPIP_R">
    <cfmDamping>0.4</cfmDamping>
  </gazebo>
  <joint name="L_THUMBCM_Y" type="revolute">
    <parent link="LARM_LINK6"/>
    <child link="L_THUMBCM_Y_LINK"/>
    <origin rpy="0 -0 0 " xyz="0 -0.0102 -0.1292"/>
    <axis xyz="0 0 -1"/>
    <limit effort="100" lower="-0.261799" upper="1.6057" velocity="0.5"/>
    <dynamics damping="0.2" friction="0"/>
  </joint>
  <transmission name="L_THUMBCM_Y_trans" type="pr2_mechanism_model/SimpleTransmission">
    <actuator name="L_THUMBCM_Y_motor"/>
    <joint name="L_THUMBCM_Y"/>
    <mechanicalReduction>1</mechanicalReduction>
  </transmission>
  <gazebo reference="L_THUMBCM_Y">
    <cfmDamping>0.4</cfmDamping>
  </gazebo>
  <joint name="L_THUMBCM_P" type="revolute">
    <parent link="L_THUMBCM_Y_LINK"/>
    <child link="L_THUMBCM_P_LINK"/>
    <origin rpy="0 -0 0 " xyz="0.045 0 0"/>
    <axis xyz="0 -1 0"/>
    <limit effort="100" lower="-0.523599" upper="1.6057" velocity="0.5"/>
    <dynamics damping="0.2" friction="0"/>
  </joint>
  <transmission name="L_THUMBCM_P_trans" type="pr2_mechanism_model/SimpleTransmission">
    <actuator name="L_THUMBCM_P_motor"/>
    <joint name="L_THUMBCM_P"/>
    <mechanicalReduction>1</mechanicalReduction>
  </transmission>
  <gazebo reference="L_THUMBCM_P">
    <cfmDamping>0.4</cfmDamping>
  </gazebo>
  <gazebo>
    <plugin filename="libIOBPlugin.so" name="hrpsys_gazebo_plugin">
      <robotname>HRP3HAND_L</robotname>
      <controller>hrpsys_gazebo_configuration</controller>
    </plugin>
  </gazebo>
  <link name="RARM_LINK6">
    <visual>
      <origin rpy="0 -0 0" xyz="0 0 0"/>
      <geometry>
        <mesh filename="package://hrpsys_gazebo_tutorials/robot_models/HRP3HAND_R/meshes/RARM_LINK6_mesh.dae" scale="1 1 1"/>
      </geometry>
    </visual>
    <collision>
      <origin rpy="0 -0 0" xyz="0 0 0"/>
      <geometry>
        <mesh filename="package://hrpsys_gazebo_tutorials/robot_models/HRP3HAND_R/meshes/RARM_LINK6_mesh.dae" scale="1 1 1"/>
      </geometry>
    </collision>
    <inertial>
      <mass value="0.001"/>
      <origin rpy="0 -0 0" xyz="0.00067085 -0.00738842 -0.085722"/>
      <inertia ixx="1e-02" ixy="0" ixz="0" iyy="1e-02" iyz="0" izz="1e-02"/>
    </inertial>
  </link>
  <gazebo reference="RARM_LINK6">
    <mu1>0.9</mu1>
    <mu2>0.9</mu2>
  </gazebo>
  <link name="R_INDEXMP_R_LINK">
    <visual>
      <origin rpy="0 -0 0" xyz="0 0.0102 -0.1547"/>
      <geometry>
        <mesh filename="package://hrpsys_gazebo_tutorials/robot_models/HRP3HAND_R/meshes/R_INDEXMP_R_LINK_mesh.dae" scale="1 1 1"/>
      </geometry>
    </visual>
    <collision>
      <origin rpy="0 -0 0" xyz="0 0.0102 -0.1547"/>
      <geometry>
        <mesh filename="package://hrpsys_gazebo_tutorials/robot_models/HRP3HAND_R/meshes/R_INDEXMP_R_LINK_mesh.dae" scale="1 1 1"/>
      </geometry>
    </collision>
    <inertial>
      <mass value="0.001"/>
      <origin rpy="0 -0 0" xyz="0.00509194 -0.00581104 6.273e-05"/>
      <inertia ixx="1e-02" ixy="0" ixz="0" iyy="1e-02" iyz="0" izz="1e-02"/>
    </inertial>
  </link>
  <gazebo reference="R_INDEXMP_R_LINK">
    <mu1>0.9</mu1>
    <mu2>0.9</mu2>
  </gazebo>
  <link name="R_INDEXMP_P_LINK">
    <visual>
      <origin rpy="0 -0 0" xyz="0.02 0 0"/>
      <geometry>
        <mesh filename="package://hrpsys_gazebo_tutorials/robot_models/HRP3HAND_R/meshes/R_INDEXMP_P_LINK_mesh.dae" scale="1 1 1"/>
      </geometry>
    </visual>
    <collision>
      <origin rpy="0 -0 0" xyz="0.02 0 0"/>
      <geometry>
        <mesh filename="package://hrpsys_gazebo_tutorials/robot_models/HRP3HAND_R/meshes/R_INDEXMP_P_LINK_mesh.dae" scale="1 1 1"/>
      </geometry>
    </collision>
    <inertial>
      <mass value="0.001"/>
      <origin rpy="0 -0 0" xyz="-0.00078463 0.00129762 -0.0281757"/>
      <inertia ixx="1e-02" ixy="0" ixz="0" iyy="1e-02" iyz="0" izz="1e-02"/>
    </inertial>
  </link>
  <gazebo reference="R_INDEXMP_P_LINK">
    <mu1>0.9</mu1>
    <mu2>0.9</mu2>
  </gazebo>
  <link name="R_INDEXPIP_R_LINK">
    <visual>
      <origin rpy="0 -0 0" xyz="0 0.01125 -0.055"/>
      <geometry>
        <mesh filename="package://hrpsys_gazebo_tutorials/robot_models/HRP3HAND_R/meshes/R_INDEXPIP_R_LINK_mesh.dae" scale="1 1 1"/>
      </geometry>
    </visual>
    <collision>
      <origin rpy="0 -0 0" xyz="0 0.01125 -0.055"/>
      <geometry>
        <mesh filename="package://hrpsys_gazebo_tutorials/robot_models/HRP3HAND_R/meshes/R_INDEXPIP_R_LINK_mesh.dae" scale="1 1 1"/>
      </geometry>
    </collision>
    <inertial>
      <mass value="0.001"/>
      <origin rpy="0 -0 0" xyz="0.0210676 0.0134797 -0.0204042"/>
      <inertia ixx="1e-02" ixy="0" ixz="0" iyy="1e-02" iyz="0" izz="1e-02"/>
    </inertial>
  </link>
  <gazebo reference="R_INDEXPIP_R_LINK">
    <mu1>0.9</mu1>
    <mu2>0.9</mu2>
  </gazebo>
  <link name="R_MIDDLEPIP_R_LINK">
    <visual>
      <origin rpy="0 -0 0" xyz="0 0.02145 -0.2097"/>
      <geometry>
        <mesh filename="package://hrpsys_gazebo_tutorials/robot_models/HRP3HAND_R/meshes/R_MIDDLEPIP_R_LINK_mesh.dae" scale="1 1 1"/>
      </geometry>
    </visual>
    <collision>
      <origin rpy="0 -0 0" xyz="0 0.02145 -0.2097"/>
      <geometry>
        <mesh filename="package://hrpsys_gazebo_tutorials/robot_models/HRP3HAND_R/meshes/R_MIDDLEPIP_R_LINK_mesh.dae" scale="1 1 1"/>
      </geometry>
    </collision>
    <inertial>
      <mass value="0.001"/>
      <origin rpy="0 -0 0" xyz="-0.0171953 0.0140037 -0.0195553"/>
      <inertia ixx="1e-02" ixy="0" ixz="0" iyy="1e-02" iyz="0" izz="1e-02"/>
    </inertial>
  </link>
  <gazebo reference="R_MIDDLEPIP_R_LINK">
    <mu1>0.9</mu1>
    <mu2>0.9</mu2>
  </gazebo>
  <link name="R_THUMBCM_Y_LINK">
    <visual>
      <origin rpy="0 -0 0" xyz="0 0.0102 -0.1292"/>
      <geometry>
        <mesh filename="package://hrpsys_gazebo_tutorials/robot_models/HRP3HAND_R/meshes/R_THUMBCM_Y_LINK_mesh.dae" scale="1 1 1"/>
      </geometry>
    </visual>
    <collision>
      <origin rpy="0 -0 0" xyz="0 0.0102 -0.1292"/>
      <geometry>
        <mesh filename="package://hrpsys_gazebo_tutorials/robot_models/HRP3HAND_R/meshes/R_THUMBCM_Y_LINK_mesh.dae" scale="1 1 1"/>
      </geometry>
    </collision>
    <inertial>
      <mass value="0.001"/>
      <origin rpy="0 -0 0" xyz="0.0314882 0.00644999 0.00140644"/>
      <inertia ixx="1e-02" ixy="0" ixz="0" iyy="1e-02" iyz="0" izz="1e-02"/>
    </inertial>
  </link>
  <gazebo reference="R_THUMBCM_Y_LINK">
    <mu1>0.9</mu1>
    <mu2>0.9</mu2>
  </gazebo>
  <link name="R_THUMBCM_P_LINK">
    <visual>
      <origin rpy="0 -0 0" xyz="0.045 0 0"/>
      <geometry>
        <mesh filename="package://hrpsys_gazebo_tutorials/robot_models/HRP3HAND_R/meshes/R_THUMBCM_P_LINK_mesh.dae" scale="1 1 1"/>
      </geometry>
    </visual>
    <collision>
      <origin rpy="0 -0 0" xyz="0.045 0 0"/>
      <geometry>
        <mesh filename="package://hrpsys_gazebo_tutorials/robot_models/HRP3HAND_R/meshes/R_THUMBCM_P_LINK_mesh.dae" scale="1 1 1"/>
      </geometry>
    </collision>
    <inertial>
      <mass value="0.001"/>
      <origin rpy="0 -0 0" xyz="0.00682086 0.013234 -0.0305205"/>
      <inertia ixx="1e-02" ixy="0" ixz="0" iyy="1e-02" iyz="0" izz="1e-02"/>
    </inertial>
  </link>
  <gazebo reference="R_THUMBCM_P_LINK">
    <mu1>0.9</mu1>
    <mu2>0.9</mu2>
  </gazebo>
  <joint name="R_INDEXMP_R" type="revolute">
    <parent link="RARM_LINK6"/>
    <child link="R_INDEXMP_R_LINK"/>
    <origin rpy="0 -0 0 " xyz="0 0.0102 -0.1547"/>
    <axis xyz="1 0 0"/>
    <limit effort="100" lower="-0.261799" upper="1.6057" velocity="0.5"/>
    <dynamics damping="0.2" friction="0"/>
  </joint>
  <transmission name="R_INDEXMP_R_trans" type="pr2_mechanism_model/SimpleTransmission">
    <actuator name="R_INDEXMP_R_motor"/>
    <joint name="R_INDEXMP_R"/>
    <mechanicalReduction>1</mechanicalReduction>
  </transmission>
  <gazebo reference="R_INDEXMP_R">
    <cfmDamping>0.4</cfmDamping>
  </gazebo>
  <joint name="R_INDEXMP_P" type="revolute">
    <parent link="R_INDEXMP_R_LINK"/>
    <child link="R_INDEXMP_P_LINK"/>
    <origin rpy="0 -0 0 " xyz="0.02 0 0"/>
    <axis xyz="0 -1 0"/>
    <limit effort="100" lower="-0" upper="1.5708" velocity="0.5"/>
    <dynamics damping="0.2" friction="0"/>
  </joint>
  <transmission name="R_INDEXMP_P_trans" type="pr2_mechanism_model/SimpleTransmission">
    <actuator name="R_INDEXMP_P_motor"/>
    <joint name="R_INDEXMP_P"/>
    <mechanicalReduction>1</mechanicalReduction>
  </transmission>
  <gazebo reference="R_INDEXMP_P">
    <cfmDamping>0.4</cfmDamping>
  </gazebo>
  <joint name="R_INDEXPIP_R" type="revolute">
    <parent link="R_INDEXMP_P_LINK"/>
    <child link="R_INDEXPIP_R_LINK"/>
    <origin rpy="0 -0 0 " xyz="0 0.01125 -0.055"/>
    <axis xyz="1 0 0"/>
    <limit effort="100" lower="-0.698132" upper="2.00713" velocity="0.5"/>
    <dynamics damping="0.2" friction="0"/>
  </joint>
  <transmission name="R_INDEXPIP_R_trans" type="pr2_mechanism_model/SimpleTransmission">
    <actuator name="R_INDEXPIP_R_motor"/>
    <joint name="R_INDEXPIP_R"/>
    <mechanicalReduction>1</mechanicalReduction>
  </transmission>
  <gazebo reference="R_INDEXPIP_R">
    <cfmDamping>0.4</cfmDamping>
  </gazebo>
  <joint name="R_MIDDLEPIP_R" type="revolute">
    <parent link="RARM_LINK6"/>
    <child link="R_MIDDLEPIP_R_LINK"/>
    <origin rpy="0 -0 0 " xyz="0 0.02145 -0.2097"/>
    <axis xyz="1 0 0"/>
    <limit effort="100" lower="-0.698132" upper="2.00713" velocity="0.5"/>
    <dynamics damping="0.2" friction="0"/>
  </joint>
  <transmission name="R_MIDDLEPIP_R_trans" type="pr2_mechanism_model/SimpleTransmission">
    <actuator name="R_MIDDLEPIP_R_motor"/>
    <joint name="R_MIDDLEPIP_R"/>
    <mechanicalReduction>1</mechanicalReduction>
  </transmission>
  <gazebo reference="R_MIDDLEPIP_R">
    <cfmDamping>0.4</cfmDamping>
  </gazebo>
  <joint name="R_THUMBCM_Y" type="revolute">
    <parent link="RARM_LINK6"/>
    <child link="R_THUMBCM_Y_LINK"/>
    <origin rpy="0 -0 0 " xyz="0 0.0102 -0.1292"/>
    <axis xyz="0 0 1"/>
    <limit effort="100" lower="-0.261799" upper="1.6057" velocity="0.5"/>
    <dynamics damping="0.2" friction="0"/>
  </joint>
  <transmission name="R_THUMBCM_Y_trans" type="pr2_mechanism_model/SimpleTransmission">
    <actuator name="R_THUMBCM_Y_motor"/>
    <joint name="R_THUMBCM_Y"/>
    <mechanicalReduction>1</mechanicalReduction>
  </transmission>
  <gazebo reference="R_THUMBCM_Y">
    <cfmDamping>0.4</cfmDamping>
  </gazebo>
  <joint name="R_THUMBCM_P" type="revolute">
    <parent link="R_THUMBCM_Y_LINK"/>
    <child link="R_THUMBCM_P_LINK"/>
    <origin rpy="0 -0 0 " xyz="0.045 0 0"/>
    <axis xyz="0 -1 0"/>
    <limit effort="100" lower="-0.523599" upper="1.6057" velocity="0.5"/>
    <dynamics damping="0.2" friction="0"/>
  </joint>
  <transmission name="R_THUMBCM_P_trans" type="pr2_mechanism_model/SimpleTransmission">
    <actuator name="R_THUMBCM_P_motor"/>
    <joint name="R_THUMBCM_P"/>
    <mechanicalReduction>1</mechanicalReduction>
  </transmission>
  <gazebo reference="R_THUMBCM_P">
    <cfmDamping>0.4</cfmDamping>
  </gazebo>
  <gazebo>
    <plugin filename="libIOBPlugin.so" name="hrpsys_gazebo_plugin">
      <robotname>HRP3HAND_R</robotname>
      <controller>hrpsys_gazebo_configuration</controller>
    </plugin>
  </gazebo>
  <joint name="LHAND_DUMMY" type="revolute">
    <origin rpy="3.14159 -1.5708 0" xyz="0.50 -0.28 0.40"/>
    <parent link="nil_link6"/>
    <child link="LARM_LINK6"/>
    <axis xyz="-1 0 0"/>
    <limit effort="100" lower="0" upper="0" velocity="0"/>
    <dynamics damping="0.2" friction="0"/>
  </joint>
  <joint name="RHAND_DUMMY" type="revolute">
    <origin rpy="3.14159 -1.5708 0" xyz="0.50 0.28 0.40"/>
    <parent link="nil_link6"/>
    <child link="RARM_LINK6"/>
    <axis xyz="-1 0 0"/>
    <limit effort="100" lower="0" upper="0" velocity="0"/>
    <dynamics damping="0.2" friction="0"/>
  </joint>
</robot>

